SELECT * FROM md_client  order by client_name ASC
SELECT * FROM td_tour_details WHERE emp_code='LSM-025' and tour_dt ='2024-08-09' order by sl_no desc limit 1
No results found for the given address.
node:internal/process/promises:288
            triggerUncaughtException(err, true /* fromPromise */);
            ^

[UnhandledPromiseRejection: This error originated either by throwing inside of an async function without a catch block, or by rejecting a promise which was not handled with .catch(). The promise rejected with the reason "#<Object>".] {
  code: 'ERR_UNHANDLED_REJECTION'
}

INSERT INTO td_tour_details (`emp_code`,`tour_dt`,`sl_no`,`visit_dtl_id`,`lat_pos`,`long_pos`,`type`,`distance`) VALUES ('LSM-012','2024-08-11 15:27:22','1','278','25.6123274','88.1335614','T','126610.37812340187')
SELECT sl_no,DATE_ADD(visit_dt, INTERVAL 1 DAY) AS visit_dt,emp_code,client_code,org_name,client_addr,dist_id,contact_person,phone_no,email_id,distance,in_time,out_time,in_out_flag,location,lat_pos,long_pos,position_name,remarks FROM td_visit_mgmt WHERE emp_code='LSM-012' AND (visit_dt = '2024-08-11' OR sch_dt = '2024-08-11')
SELECT * FROM td_tour_details WHERE emp_code='LSM-012' and tour_dt ='2024-08-11' order by sl_no desc limit 1
SELECT * FROM md_client  order by client_name ASC
No results found for the given address.
node:internal/process/promises:288
            triggerUncaughtException(err, true /* fromPromise */);
            ^

[UnhandledPromiseRejection: This error originated either by throwing inside of an async function without a catch block, or by rejecting a promise which was not handled with .catch(). The promise rejected with the reason "#<Object>".] {
  code: 'ERR_UNHANDLED_REJECTION'
}

Node.js v18.17.1
[nodemon] app crashed - waiting for file changes before starting...
^X^C

SELECT sl_no,DATE_ADD(visit_dt, INTERVAL 1 DAY) AS visit_dt,emp_code,client_code,org_name,client_addr,dist_id,contact_person,phone_no,email_id,distance,in_time,out_time,in_out_flag,location,lat_pos,long_pos,position_name,remarks FROM td_visit_mgmt WHERE emp_code='LSM-025' AND (visit_dt = '2024-08-19' OR sch_dt = '2024-08-19')
No results found for the given address.
node:internal/process/promises:288
            triggerUncaughtException(err, true /* fromPromise */);
            ^

[UnhandledPromiseRejection: This error originated either by throwing inside of an async function without a catch block, or by rejecting a promise which was not handled with .catch(). The promise rejected with the reason "#<Object>".] {
  code: 'ERR_UNHANDLED_REJECTION'
}

SELECT * FROM td_attendance WHERE emp_code='127' AND atten_dt='2024-08-22'
No results found for the given address.
node:internal/process/promises:288
            triggerUncaughtException(err, true /* fromPromise */);
            ^

[UnhandledPromiseRejection: This error originated either by throwing inside of an async function without a catch block, or by rejecting a promise which was not handled with .catch(). The promise rejected with the reason "#<Object>".] {
  code: 'ERR_UNHANDLED_REJECTION'
}

Node.js v18.17.1
[nodemon] app crashed - waiting for file changes before starting...

UPDATE td_visit_mgmt SET contact_person = 'Mr. Biswarup ', phone_no = '9830957105', email_id = '', out_time = '13:37:58',in_out_flag = 'O', position_name ='601, Diamond Harbour Rd, Manton, Behala, Kolkata, West Bengal 700034, India' ,remarks = 'He is bit busy today. told me that call today evening. Also meet Bio-Medical Mr. Avishek ( Bio-Medical) Regarding order of Syringe Pump. he told me it will take more time . call him regarding machin in month of March.',modified_by = 'LSM-018',modified_dt = '2024-12-13 13:37:58' WHERE sl_no = '1222'
[Object: null prototype] { user_id: 'LSM-025', password: 'tapesh1973' }
INSERT INTO td_log (ip_address,mac_addr,log_date,user_id,task) VALUES ('0.0.0.0','0.0.0.0','2024-12-13 13:12:54','LSM-025','MLOGIN')
No results found for the given address.
node:internal/process/promises:288
            triggerUncaughtException(err, true /* fromPromise */);
            ^

[UnhandledPromiseRejection: This error originated either by throwing inside of an async function without a catch block, or by rejecting a promise which was not handled with .catch(). The promise rejected with the reason "#<Object>".] {
  code: 'ERR_UNHANDLED_REJECTION'
}


INSERT INTO td_log (ip_address,mac_addr,log_date,user_id,task) VALUES ('0.0.0.0','0.0.0.0','2024-12-31 11:12:09','lsm-024','MLOGIN')
No results found for the given address.
node:internal/process/promises:288
            triggerUncaughtException(err, true /* fromPromise */);
            ^

[UnhandledPromiseRejection: This error originated either by throwing inside of an async function without a catch block, or by rejecting a promise which was not handled with .catch(). The promise rejected with the reason "#<Object>".] {
  code: 'ERR_UNHANDLED_REJECTION'
}